<?xml version="1.0" ?>
<!-- =================================================================================== -->
<!-- |    This document was autogenerated by xacro from lapras_urdf.xacro              | -->
<!-- |    EDITING THIS FILE BY HAND IS NOT RECOMMENDED                                 | -->
<!-- =================================================================================== -->
<robot name="lapras_urdf">
  <material name="silver">
    <color rgba="0.700 0.700 0.700 1.000"/>
  </material>
  <transmission name="left_wheel_joint_tran">
    <type>transmission_interface/SimpleTransmission</type>
    <joint name="left_wheel_joint">
      <hardwareInterface>hardware_interface/EffortJointInterface</hardwareInterface>
    </joint>
    <actuator name="left_wheel_joint_actr">
      <hardwareInterface>hardware_interface/EffortJointInterface</hardwareInterface>
      <mechanicalReduction>1</mechanicalReduction>
    </actuator>
  </transmission>
  <transmission name="right_wheel_joint_tran">
    <type>transmission_interface/SimpleTransmission</type>
    <joint name="right_wheel_joint">
      <hardwareInterface>hardware_interface/EffortJointInterface</hardwareInterface>
    </joint>
    <actuator name="right_wheel_joint_actr">
      <hardwareInterface>hardware_interface/EffortJointInterface</hardwareInterface>
      <mechanicalReduction>1</mechanicalReduction>
    </actuator>
  </transmission>
  <gazebo>
    <plugin filename="libgazebo_ros_control.so" name="control"/>
  </gazebo>
  <gazebo reference="base_link">
    <material>Gazebo/Silver</material>
    <mu1>0.2</mu1>
    <mu2>0.2</mu2>
    <selfCollide>true</selfCollide>
    <gravity>true</gravity>
  </gazebo>
  <gazebo reference="MotorBracket_v1_1">
    <material>Gazebo/Silver</material>
    <mu1>0.2</mu1>
    <mu2>0.2</mu2>
    <selfCollide>true</selfCollide>
  </gazebo>
  <gazebo reference="MotorBracket_v1__1__1">
    <material>Gazebo/Silver</material>
    <mu1>0.2</mu1>
    <mu2>0.2</mu2>
    <selfCollide>true</selfCollide>
  </gazebo>
  <gazebo reference="Motor_v1__1__1">
    <material>Gazebo/Silver</material>
    <mu1>0.2</mu1>
    <mu2>0.2</mu2>
    <selfCollide>true</selfCollide>
  </gazebo>
  <gazebo reference="Motor_v1_1">
    <material>Gazebo/Silver</material>
    <mu1>0.2</mu1>
    <mu2>0.2</mu2>
    <selfCollide>true</selfCollide>
  </gazebo>
  <gazebo reference="ydlidar_base_v5_1">
    <material>Gazebo/Silver</material>
    <mu1>0.2</mu1>
    <mu2>0.2</mu2>
    <selfCollide>true</selfCollide>
  </gazebo>
  <gazebo reference="Barbell_v4__2__1">
    <material>Gazebo/Silver</material>
    <mu1>0.2</mu1>
    <mu2>0.2</mu2>
    <selfCollide>true</selfCollide>
  </gazebo>
  <gazebo reference="Barbell_v4__1__1">
    <material>Gazebo/Silver</material>
    <mu1>0.2</mu1>
    <mu2>0.2</mu2>
    <selfCollide>true</selfCollide>
  </gazebo>
  <gazebo reference="Barbell_v4_1">
    <material>Gazebo/Silver</material>
    <mu1>0.2</mu1>
    <mu2>0.2</mu2>
    <selfCollide>true</selfCollide>
  </gazebo>
  <gazebo reference="mid_base_v8_1">
    <material>Gazebo/Silver</material>
    <mu1>0.2</mu1>
    <mu2>0.2</mu2>
    <selfCollide>true</selfCollide>
  </gazebo>
  <gazebo reference="ydlidar_x4_v1_1">
    <material>Gazebo/Silver</material>
    <mu1>0.2</mu1>
    <mu2>0.2</mu2>
    <selfCollide>true</selfCollide>
  </gazebo>
  <gazebo reference="topper_base_v7_1">
    <material>Gazebo/Silver</material>
    <mu1>0.2</mu1>
    <mu2>0.2</mu2>
    <selfCollide>true</selfCollide>
  </gazebo>
  <gazebo reference="left_wheel_1">
    <material>Gazebo/Silver</material>
    <mu1>0.2</mu1>
    <mu2>0.2</mu2>
    <selfCollide>true</selfCollide>
  </gazebo>
  <gazebo reference="right_wheel_1">
    <material>Gazebo/Silver</material>
    <mu1>0.2</mu1>
    <mu2>0.2</mu2>
    <selfCollide>true</selfCollide>
  </gazebo>
  <gazebo reference="caster_urdf_v2_1">
    <material>Gazebo/Silver</material>
    <mu1>0.2</mu1>
    <mu2>0.2</mu2>
    <selfCollide>true</selfCollide>
  </gazebo>
  <gazebo reference="caster_urdf_v2__1__1">
    <material>Gazebo/Silver</material>
    <mu1>0.2</mu1>
    <mu2>0.2</mu2>
    <selfCollide>true</selfCollide>
  </gazebo>
  <link name="base_link">
    <inertial>
      <origin rpy="0 0 0" xyz="0.003378781940864467 2.240969994186515e-06 0.06345999999999999"/>
      <mass value="2.66119702526629"/>
      <inertia ixx="0.00974" ixy="0.0" ixz="-0.0" iyy="0.026333" iyz="-0.0" izz="0.036062"/>
    </inertial>
    <visual>
      <origin rpy="0 0 0" xyz="0 0 0"/>
      <geometry>
        <mesh filename="package://lapras_sim/meshes/base_link.stl" scale="0.001 0.001 0.001"/>
      </geometry>
      <material name="silver"/>
    </visual>
    <collision>
      <origin rpy="0 0 0" xyz="0 0 0"/>
      <geometry>
        <mesh filename="package://lapras_sim/meshes/base_link.stl" scale="0.001 0.001 0.001"/>
      </geometry>
    </collision>
  </link>
  <link name="MotorBracket_v1_1">
    <inertial>
      <origin rpy="0 0 0" xyz="-0.015500002350700986 -0.006888187169975468 0.007341692818743625"/>
      <mass value="0.029603665959913542"/>
      <inertia ixx="9e-06" ixy="-0.0" ixz="0.0" iyy="8e-06" iyz="-2e-06" izz="9e-06"/>
    </inertial>
    <visual>
      <origin rpy="0 0 0" xyz="-0.0155 -0.09 -0.06596"/>
      <geometry>
        <mesh filename="package://lapras_sim/meshes/MotorBracket_v1_1.stl" scale="0.001 0.001 0.001"/>
      </geometry>
      <material name="silver"/>
    </visual>
    <collision>
      <origin rpy="0 0 0" xyz="-0.0155 -0.09 -0.06596"/>
      <geometry>
        <mesh filename="package://lapras_sim/meshes/MotorBracket_v1_1.stl" scale="0.001 0.001 0.001"/>
      </geometry>
    </collision>
  </link>
  <link name="MotorBracket_v1__1__1">
    <inertial>
      <origin rpy="0 0 0" xyz="0.01550000235070098 0.006888187169975399 0.007341692818743681"/>
      <mass value="0.029603665959913542"/>
      <inertia ixx="9e-06" ixy="-0.0" ixz="-0.0" iyy="8e-06" iyz="2e-06" izz="9e-06"/>
    </inertial>
    <visual>
      <origin rpy="0 0 0" xyz="0.0155 0.09 -0.06596"/>
      <geometry>
        <mesh filename="package://lapras_sim/meshes/MotorBracket_v1__1__1.stl" scale="0.001 0.001 0.001"/>
      </geometry>
      <material name="silver"/>
    </visual>
    <collision>
      <origin rpy="0 0 0" xyz="0.0155 0.09 -0.06596"/>
      <geometry>
        <mesh filename="package://lapras_sim/meshes/MotorBracket_v1__1__1.stl" scale="0.001 0.001 0.001"/>
      </geometry>
    </collision>
  </link>
  <link name="Motor_v1__1__1">
    <inertial>
      <origin rpy="0 0 0" xyz="-0.009191401001469089 -0.03790852980642254 0.009191999999481462"/>
      <mass value="0.47787780551719694"/>
      <inertia ixx="0.000299" ixy="-0.0" ixz="-0.0" iyy="5.6e-05" iyz="0.0" izz="0.000299"/>
    </inertial>
    <visual>
      <origin rpy="0 0 0" xyz="-0.009192 -0.094569 -0.075837"/>
      <geometry>
        <mesh filename="package://lapras_sim/meshes/Motor_v1__1__1.stl" scale="0.001 0.001 0.001"/>
      </geometry>
      <material name="silver"/>
    </visual>
    <collision>
      <origin rpy="0 0 0" xyz="-0.009192 -0.094569 -0.075837"/>
      <geometry>
        <mesh filename="package://lapras_sim/meshes/Motor_v1__1__1.stl" scale="0.001 0.001 0.001"/>
      </geometry>
    </collision>
  </link>
  <link name="Motor_v1_1">
    <inertial>
      <origin rpy="0 0 0" xyz="-0.009191400405422592 0.03790852980642258 0.009192000000518591"/>
      <mass value="0.47787780551719694"/>
      <inertia ixx="0.000299" ixy="0.0" ixz="0.0" iyy="5.6e-05" iyz="0.0" izz="0.000299"/>
    </inertial>
    <visual>
      <origin rpy="0 0 0" xyz="-0.009192 0.094569 -0.075837"/>
      <geometry>
        <mesh filename="package://lapras_sim/meshes/Motor_v1_1.stl" scale="0.001 0.001 0.001"/>
      </geometry>
      <material name="silver"/>
    </visual>
    <collision>
      <origin rpy="0 0 0" xyz="-0.009192 0.094569 -0.075837"/>
      <geometry>
        <mesh filename="package://lapras_sim/meshes/Motor_v1_1.stl" scale="0.001 0.001 0.001"/>
      </geometry>
    </collision>
  </link>
  <link name="ydlidar_base_v5_1">
    <inertial>
      <origin rpy="0 0 0" xyz="0.06761097664511198 0.020859849955070977 0.008623214289900732"/>
      <mass value="0.469663968235366"/>
      <inertia ixx="0.000427" ixy="-0.0" ixz="-6.2e-05" iyy="0.000887" iyz="0.0" izz="0.001181"/>
    </inertial>
    <visual>
      <origin rpy="0 0 0" xyz="-0.11914 0.02086 -0.06596"/>
      <geometry>
        <mesh filename="package://lapras_sim/meshes/ydlidar_base_v5_1.stl" scale="0.001 0.001 0.001"/>
      </geometry>
      <material name="silver"/>
    </visual>
    <collision>
      <origin rpy="0 0 0" xyz="-0.11914 0.02086 -0.06596"/>
      <geometry>
        <mesh filename="package://lapras_sim/meshes/ydlidar_base_v5_1.stl" scale="0.001 0.001 0.001"/>
      </geometry>
    </collision>
  </link>
  <link name="Barbell_v4__2__1">
    <inertial>
      <origin rpy="0 0 0" xyz="-5.551115123125783e-17 -3.1879089884571067e-15 0.052581463666413836"/>
      <mass value="0.09798102385329209"/>
      <inertia ixx="0.000112" ixy="0.0" ixz="0.0" iyy="0.000102" iyz="-0.0" izz="1.1e-05"/>
    </inertial>
    <visual>
      <origin rpy="0 0 0" xyz="-0.09 -0.0 -0.06596"/>
      <geometry>
        <mesh filename="package://lapras_sim/meshes/Barbell_v4__2__1.stl" scale="0.001 0.001 0.001"/>
      </geometry>
      <material name="silver"/>
    </visual>
    <collision>
      <origin rpy="0 0 0" xyz="-0.09 -0.0 -0.06596"/>
      <geometry>
        <mesh filename="package://lapras_sim/meshes/Barbell_v4__2__1.stl" scale="0.001 0.001 0.001"/>
      </geometry>
    </collision>
  </link>
  <link name="Barbell_v4__1__1">
    <inertial>
      <origin rpy="0 0 0" xyz="-3.2057689836051395e-15 -1.3877787807814457e-17 0.052581463666413794"/>
      <mass value="0.09798102385329208"/>
      <inertia ixx="0.000102" ixy="0.0" ixz="-0.0" iyy="0.000112" iyz="0.0" izz="1.1e-05"/>
    </inertial>
    <visual>
      <origin rpy="0 0 0" xyz="0.072 0.08 -0.06596"/>
      <geometry>
        <mesh filename="package://lapras_sim/meshes/Barbell_v4__1__1.stl" scale="0.001 0.001 0.001"/>
      </geometry>
      <material name="silver"/>
    </visual>
    <collision>
      <origin rpy="0 0 0" xyz="0.072 0.08 -0.06596"/>
      <geometry>
        <mesh filename="package://lapras_sim/meshes/Barbell_v4__1__1.stl" scale="0.001 0.001 0.001"/>
      </geometry>
    </collision>
  </link>
  <link name="Barbell_v4_1">
    <inertial>
      <origin rpy="0 0 0" xyz="3.1780134079895106e-15 0.0 0.05258146366641378"/>
      <mass value="0.09798102385329209"/>
      <inertia ixx="0.000102" ixy="0.0" ixz="0.0" iyy="0.000112" iyz="0.0" izz="1.1e-05"/>
    </inertial>
    <visual>
      <origin rpy="0 0 0" xyz="0.072 -0.08 -0.06596"/>
      <geometry>
        <mesh filename="package://lapras_sim/meshes/Barbell_v4_1.stl" scale="0.001 0.001 0.001"/>
      </geometry>
      <material name="silver"/>
    </visual>
    <collision>
      <origin rpy="0 0 0" xyz="0.072 -0.08 -0.06596"/>
      <geometry>
        <mesh filename="package://lapras_sim/meshes/Barbell_v4_1.stl" scale="0.001 0.001 0.001"/>
      </geometry>
    </collision>
  </link>
  <link name="mid_base_v8_1">
    <inertial>
      <origin rpy="0 0 0" xyz="0.07124371334793965 -0.0799683699998151 0.001500000000000043"/>
      <mass value="0.49453185821915246"/>
      <inertia ixx="0.000754" ixy="4e-06" ixz="0.0" iyy="0.001164" iyz="0.0" izz="0.001918"/>
    </inertial>
    <visual>
      <origin rpy="0 0 0" xyz="0.0905 -0.08 -0.12021"/>
      <geometry>
        <mesh filename="package://lapras_sim/meshes/mid_base_v8_1.stl" scale="0.001 0.001 0.001"/>
      </geometry>
      <material name="silver"/>
    </visual>
    <collision>
      <origin rpy="0 0 0" xyz="0.0905 -0.08 -0.12021"/>
      <geometry>
        <mesh filename="package://lapras_sim/meshes/mid_base_v8_1.stl" scale="0.001 0.001 0.001"/>
      </geometry>
    </collision>
  </link>
  <link name="ydlidar_x4_v1_1">
    <inertial>
      <origin rpy="0 0 0" xyz="0.03029455171374079 0.030999849954996873 0.03770114222279111"/>
      <mass value="1.1515616542314233"/>
      <inertia ixx="0.000489" ixy="-0.0" ixz="0.000148" iyy="0.000861" iyz="-0.0" izz="0.000987"/>
    </inertial>
    <visual>
      <origin rpy="0 0 0" xyz="-0.168364 0.031 -0.06996"/>
      <geometry>
        <mesh filename="package://lapras_sim/meshes/ydlidar_x4_v1_1.stl" scale="0.001 0.001 0.001"/>
      </geometry>
      <material name="silver"/>
    </visual>
    <collision>
      <origin rpy="0 0 0" xyz="-0.168364 0.031 -0.06996"/>
      <geometry>
        <mesh filename="package://lapras_sim/meshes/ydlidar_x4_v1_1.stl" scale="0.001 0.001 0.001"/>
      </geometry>
    </collision>
  </link>
  <link name="topper_base_v7_1">
    <inertial>
      <origin rpy="0 0 0" xyz="0.07230390007609636 -0.07999999999999996 0.0024999999999999745"/>
      <mass value="3.18470053243339"/>
      <inertia ixx="0.016652" ixy="0.0" ixz="0.0" iyy="0.029765" iyz="0.0" izz="0.046404"/>
    </inertial>
    <visual>
      <origin rpy="0 0 0" xyz="0.072 -0.08 -0.17096"/>
      <geometry>
        <mesh filename="package://lapras_sim/meshes/topper_base_v7_1.stl" scale="0.001 0.001 0.001"/>
      </geometry>
      <material name="silver"/>
    </visual>
    <collision>
      <origin rpy="0 0 0" xyz="0.072 -0.08 -0.17096"/>
      <geometry>
        <mesh filename="package://lapras_sim/meshes/topper_base_v7_1.stl" scale="0.001 0.001 0.001"/>
      </geometry>
    </collision>
  </link>
  <link name="left_wheel_1">
    <inertial>
      <origin rpy="0 0 0" xyz="-2.979255688107887e-10 0.015140536035911395 1.3877787807814457e-17"/>
      <mass value="2.7295236460278423"/>
      <inertia ixx="0.002744" ixy="-0.0" ixz="0.0" iyy="0.005075" iyz="0.0" izz="0.002744"/>
    </inertial>
    <visual>
      <origin rpy="0 0 0" xyz="0.0 -0.113869 -0.085029"/>
      <geometry>
        <mesh filename="package://lapras_sim/meshes/left_wheel_1.stl" scale="0.001 0.001 0.001"/>
      </geometry>
      <material name="silver"/>
    </visual>
    <collision>
      <origin rpy="0 0 0" xyz="0.0 -0.113869 -0.085029"/>
      <geometry>
        <mesh filename="package://lapras_sim/meshes/left_wheel_1.stl" scale="0.001 0.001 0.001"/>
      </geometry>
    </collision>
  </link>
  <link name="right_wheel_1">
    <inertial>
      <origin rpy="0 0 0" xyz="2.981209200907584e-10 -0.015140536035911367 9.71445146547012e-17"/>
      <mass value="2.7295236460278423"/>
      <inertia ixx="0.002744" ixy="0.0" ixz="0.0" iyy="0.005075" iyz="0.0" izz="0.002744"/>
    </inertial>
    <visual>
      <origin rpy="0 0 0" xyz="-0.0 0.113869 -0.085029"/>
      <geometry>
        <mesh filename="package://lapras_sim/meshes/right_wheel_1.stl" scale="0.001 0.001 0.001"/>
      </geometry>
      <material name="silver"/>
    </visual>
    <collision>
      <origin rpy="0 0 0" xyz="-0.0 0.113869 -0.085029"/>
      <geometry>
        <mesh filename="package://lapras_sim/meshes/right_wheel_1.stl" scale="0.001 0.001 0.001"/>
      </geometry>
    </collision>
  </link>
  <link name="caster_urdf_v4__1__1">
    <inertial>
      <origin rpy="0 0 0" xyz="-9.828451930510296e-06 4.13190816823857e-06 -0.00964031607284841"/>
      <mass value="0.14226334327662343"/>
      <inertia ixx="1.9e-05" ixy="0.0" ixz="-0.0" iyy="2.2e-05" iyz="0.0" izz="2.3e-05"/>
    </inertial>
    <visual>
      <origin rpy="0 0 0" xyz="-0.14 -0.0 -0.06096"/>
      <geometry>
        <mesh filename="package://lapras_sim/meshes/caster_urdf_v4__1__1.stl" scale="0.001 0.001 0.001"/>
      </geometry>
      <material name="silver"/>
    </visual>
    <collision>
      <origin rpy="0 0 0" xyz="-0.14 -0.0 -0.06096"/>
      <geometry>
        <mesh filename="package://lapras_sim/meshes/caster_urdf_v4__1__1.stl" scale="0.001 0.001 0.001"/>
      </geometry>
    </collision>
  </link>
  <link name="caster_urdf_v4_1">
    <inertial>
      <origin rpy="0 0 0" xyz="0.012490171548069612 0.009504131908168236 -0.00964031607284841"/>
      <mass value="0.14226334327662343"/>
      <inertia ixx="1.9e-05" ixy="0.0" ixz="-0.0" iyy="2.2e-05" iyz="0.0" izz="2.3e-05"/>
    </inertial>
    <visual>
      <origin rpy="0 0 0" xyz="0.14 0.0095 -0.06096"/>
      <geometry>
        <mesh filename="package://lapras_sim/meshes/caster_urdf_v4_1.stl" scale="0.001 0.001 0.001"/>
      </geometry>
      <material name="silver"/>
    </visual>
    <collision>
      <origin rpy="0 0 0" xyz="0.14 0.0095 -0.06096"/>
      <geometry>
        <mesh filename="package://lapras_sim/meshes/caster_urdf_v4_1.stl" scale="0.001 0.001 0.001"/>
      </geometry>
    </collision>
  </link>
  <joint name="Rigid29" type="fixed">
    <origin rpy="0 0 0" xyz="0.0155 0.09 0.06596"/>
    <parent link="base_link"/>
    <child link="MotorBracket_v1_1"/>
  </joint>
  <joint name="Rigid30" type="fixed">
    <origin rpy="0 0 0" xyz="-0.0155 -0.09 0.06596"/>
    <parent link="base_link"/>
    <child link="MotorBracket_v1__1__1"/>
  </joint>
  <joint name="Rigid31" type="fixed">
    <origin rpy="0 0 0" xyz="-0.006308 0.004569 0.009877"/>
    <parent link="MotorBracket_v1_1"/>
    <child link="Motor_v1__1__1"/>
  </joint>
  <joint name="Rigid32" type="fixed">
    <origin rpy="0 0 0" xyz="0.024692 -0.004569 0.009877"/>
    <parent link="MotorBracket_v1__1__1"/>
    <child link="Motor_v1_1"/>
  </joint>
  <joint name="Rigid35" type="fixed">
    <origin rpy="0 0 0" xyz="0.11914 -0.02086 0.06596"/>
    <parent link="base_link"/>
    <child link="ydlidar_base_v5_1"/>
  </joint>
  <joint name="Rigid36" type="fixed">
    <origin rpy="0 0 0" xyz="0.09 0.0 0.06596"/>
    <parent link="base_link"/>
    <child link="Barbell_v4__2__1"/>
  </joint>
  <joint name="Rigid37" type="fixed">
    <origin rpy="0 0 0" xyz="-0.072 -0.08 0.06596"/>
    <parent link="base_link"/>
    <child link="Barbell_v4__1__1"/>
  </joint>
  <joint name="Rigid38" type="fixed">
    <origin rpy="0 0 0" xyz="-0.072 0.08 0.06596"/>
    <parent link="base_link"/>
    <child link="Barbell_v4_1"/>
  </joint>
  <joint name="Rigid39" type="fixed">
    <origin rpy="0 0 0" xyz="-0.0185 0.0 0.05425"/>
    <parent link="Barbell_v4_1"/>
    <child link="mid_base_v8_1"/>
  </joint>
  <joint name="Rigid40" type="fixed">
    <origin rpy="0 0 0" xyz="0.049224 -0.01014 0.004"/>
    <parent link="ydlidar_base_v5_1"/>
    <child link="ydlidar_x4_v1_1"/>
  </joint>
  <joint name="Rigid41" type="fixed">
    <origin rpy="0 0 0" xyz="0.0 0.0 0.105"/>
    <parent link="Barbell_v4_1"/>
    <child link="topper_base_v7_1"/>
  </joint>
  <joint name="left_wheel_joint" type="continuous">
    <origin rpy="0 0 0" xyz="-0.009192 0.0193 0.009192"/>
    <parent link="Motor_v1__1__1"/>
    <child link="left_wheel_1"/>
    <axis xyz="0.0 1.0 0.0"/>
  </joint>
  <joint name="right_wheel_joint" type="continuous">
    <origin rpy="0 0 0" xyz="-0.009192 -0.0193 0.009192"/>
    <parent link="Motor_v1_1"/>
    <child link="right_wheel_1"/>
    <axis xyz="-0.0 -1.0 0.0"/>
  </joint>
  <joint name="Rigid50" type="fixed">
    <origin rpy="0 0 0" xyz="0.14 0.0 0.06096"/>
    <parent link="base_link"/>
    <child link="caster_urdf_v4__1__1"/>
  </joint>
  <joint name="Rigid51" type="fixed">
    <origin rpy="0 0 0" xyz="-0.14 -0.0095 0.06096"/>
    <parent link="base_link"/>
    <child link="caster_urdf_v4_1"/>
  </joint>
</robot>
